// Copyright (c) Microsoft Corporation. All rights reserved.
// Licensed under the MIT license. See LICENSE file in the project root for full license information.

using System.Diagnostics;
using System.Diagnostics.CodeAnalysis;
using System.Globalization;
using System.Reflection;
using System.Text;

using Microsoft.VisualStudio.TestPlatform.MSTest.TestAdapter.Extensions;
using Microsoft.VisualStudio.TestPlatform.MSTest.TestAdapter.Helpers;
using Microsoft.VisualStudio.TestPlatform.MSTest.TestAdapter.ObjectModel;
using Microsoft.VisualStudio.TestTools.UnitTesting;

using ObjectModelUnitTestOutcome = Microsoft.VisualStudio.TestPlatform.MSTest.TestAdapter.ObjectModel.UnitTestOutcome;
using UTF = Microsoft.VisualStudio.TestTools.UnitTesting;

namespace Microsoft.VisualStudio.TestPlatform.MSTest.TestAdapter.Execution;

/// <summary>
/// Defines the TestMethod Info object.
/// </summary>
public class TestMethodInfo : ITestMethod
{
    /// <summary>
    /// Specifies the timeout when it is not set in a test case.
    /// </summary>
    public const int TimeoutWhenNotSet = 0;

    internal TestMethodInfo(
        MethodInfo testMethod,
        TestClassInfo parent,
        TestMethodOptions testMethodOptions)
    {
        DebugEx.Assert(testMethod != null, "TestMethod should not be null");
        DebugEx.Assert(parent != null, "Parent should not be null");

        TestMethod = testMethod;
        Parent = parent;
        TestMethodOptions = testMethodOptions;
    }

    /// <summary>
    /// Gets a value indicating whether timeout is set.
    /// </summary>
    public bool IsTimeoutSet => TestMethodOptions.Timeout != TimeoutWhenNotSet;

    /// <summary>
    /// Gets the reason why the test is not runnable.
    /// </summary>
    public string? NotRunnableReason { get; internal set; }

    /// <summary>
    /// Gets a value indicating whether test is runnable.
    /// </summary>
    public bool IsRunnable => StringEx.IsNullOrEmpty(NotRunnableReason);

    public ParameterInfo[] ParameterTypes => TestMethod.GetParameters();

    public Type ReturnType => TestMethod.ReturnType;

    public string TestClassName => Parent.ClassType.FullName!;

    public string TestMethodName => TestMethod.Name;

    public MethodInfo MethodInfo => TestMethod;

    public object?[]? Arguments { get; private set; }

    /// <summary>
    /// Gets testMethod referred by this object.
    /// </summary>
    internal MethodInfo TestMethod { get; }

    /// <summary>
    /// Gets the parent class Info object.
    /// </summary>
    internal TestClassInfo Parent { get; }

    /// <summary>
    /// Gets the options for the test method in this environment.
    /// </summary>
    internal TestMethodOptions TestMethodOptions { get; }

    public Attribute[]? GetAllAttributes(bool inherit) => ReflectHelper.GetCustomAttributes(TestMethod, inherit) as Attribute[];

    public TAttributeType[] GetAttributes<TAttributeType>(bool inherit)
        where TAttributeType : Attribute
        => ReflectHelper.GetAttributes<TAttributeType>(TestMethod, inherit)
        ?? Array.Empty<TAttributeType>();

    /// <summary>
    /// Execute test method. Capture failures, handle async and return result.
    /// </summary>
    /// <param name="arguments">
    ///  Arguments to pass to test method. (E.g. For data driven).
    /// </param>
    /// <returns>Result of test method invocation.</returns>
    public virtual TestResult Invoke(object?[]? arguments)
    {
        Stopwatch watch = new();
        TestResult? result = null;

        // check if arguments are set for data driven tests
        arguments ??= Arguments;

        using (LogMessageListener listener = new(TestMethodOptions.CaptureDebugTraces))
        {
            watch.Start();
            try
            {
                result = IsTimeoutSet ? ExecuteInternalWithTimeout(arguments) : ExecuteInternal(arguments);
            }
            finally
            {
                // Handle logs & debug traces.
                watch.Stop();

                if (result != null)
                {
                    result.Duration = watch.Elapsed;
                    result.DebugTrace = listener.GetAndClearDebugTrace();
                    result.LogOutput = listener.GetAndClearStandardOutput();
                    result.LogError = listener.GetAndClearStandardError();
                    result.TestContextMessages = TestMethodOptions.TestContext?.GetAndClearDiagnosticMessages();
                    result.ResultFiles = TestMethodOptions.TestContext?.GetResultFiles();
                }
            }
        }

        return result;
    }

    internal void SetArguments(object?[]? arguments) => Arguments = arguments == null ? null : ResolveArguments(arguments);

    internal object?[] ResolveArguments(object?[] arguments)
    {
        ParameterInfo[] parametersInfo = TestMethod.GetParameters();
        int requiredParameterCount = 0;
        bool hasParamsValue = false;
        object? paramsValues = null;
        foreach (ParameterInfo parameter in parametersInfo)
        {
            // If this is a params array parameter, create an instance to
            // populate with any extra values provided. Don't increment
            // required parameter count - params arguments are not actually required
            if (parameter.GetCustomAttribute(typeof(ParamArrayAttribute)) != null)
            {
                hasParamsValue = true;
                break;
            }

            // Count required parameters from method
            if (!parameter.IsOptional)
            {
                requiredParameterCount++;
            }
        }

        // If all the parameters are required, we have fewer arguments
        // supplied than required, or more arguments than the method takes
        // and it doesn't have a params parameter don't try and resolve anything
        if (requiredParameterCount == parametersInfo.Length ||
            arguments.Length < requiredParameterCount ||
            (!hasParamsValue && arguments.Length > parametersInfo.Length))
        {
            return arguments;
        }

        object?[] newParameters = new object[parametersInfo.Length];
        for (int argumentIndex = 0; argumentIndex < arguments.Length; argumentIndex++)
        {
            // We have reached the end of the regular parameters and any additional
            // values will go in a params array
            if (argumentIndex >= parametersInfo.Length - 1 && hasParamsValue)
            {
                // If this is the params parameter, instantiate a new object of that type
                if (argumentIndex == parametersInfo.Length - 1)
                {
                    paramsValues = Activator.CreateInstance(parametersInfo[argumentIndex].ParameterType, new object[] { arguments.Length - argumentIndex });
                    newParameters[argumentIndex] = paramsValues;
                }

                // The params parameters is an array but the type is not known
                // set the values as a generic array
                if (paramsValues is Array paramsArray)
                {
                    paramsArray.SetValue(arguments[argumentIndex], argumentIndex - (parametersInfo.Length - 1));
                }
            }
            else
            {
                newParameters[argumentIndex] = arguments[argumentIndex];
            }
        }

        // If arguments supplied are less than total possible arguments set
        // the values supplied to the default values for those parameters
        for (int parameterNotProvidedIndex = arguments.Length; parameterNotProvidedIndex < parametersInfo.Length; parameterNotProvidedIndex++)
        {
            // If this is the params parameters, set it to an empty
            // array of that type as DefaultValue is DBNull
            newParameters[parameterNotProvidedIndex] = hasParamsValue && parameterNotProvidedIndex == parametersInfo.Length - 1
                ? Activator.CreateInstance(parametersInfo[parameterNotProvidedIndex].ParameterType, 0)
                : parametersInfo[parameterNotProvidedIndex].DefaultValue;
        }

        return newParameters;
    }

    /// <summary>
    /// Execute test without timeout.
    /// </summary>
    /// <param name="arguments">Arguments to be passed to the method.</param>
    /// <returns>The result of the execution.</returns>
    [SuppressMessage("Microsoft.Design", "CA1031:DoNotCatchGeneralExceptionTypes", Justification = "Requirement is to handle all kinds of user exceptions and message appropriately.")]
    private TestResult ExecuteInternal(object?[]? arguments)
    {
        DebugEx.Assert(TestMethod != null, "UnitTestExecuter.DefaultTestMethodInvoke: testMethod = null.");

        var result = new TestResult();

        // TODO remove dry violation with TestMethodRunner
        object? classInstance = CreateTestClassInstance(result);
        bool testContextSetup = false;
        bool isExceptionThrown = false;
        bool hasTestInitializePassed = false;
        Exception? testRunnerException = null;

        try
        {
            try
            {
                if (classInstance != null && SetTestContext(classInstance, result))
                {
                    // For any failure after this point, we must run TestCleanup
                    testContextSetup = true;

                    if (RunTestInitializeMethod(classInstance, result))
                    {
                        hasTestInitializePassed = true;
                        TestMethod.InvokeAsSynchronousTask(classInstance, arguments);
                        result.Outcome = UTF.UnitTestOutcome.Passed;
                    }
                }
            }
            catch (Exception ex)
            {
                isExceptionThrown = true;
                Exception realException = GetRealException(ex);

                if (realException is MissingMethodException)
                {
                    result.Outcome = UTF.UnitTestOutcome.NotFound;
                    result.TestFailureException = realException;
                }
                else
                {
                    if (IsExpectedException(realException, result))
                    {
                        // Expected Exception was thrown, so Pass the test
                        result.Outcome = UTF.UnitTestOutcome.Passed;
                    }
                    else
                    {
                        // This block should not throw. If it needs to throw, then handling of
                        // ThreadAbortException will need to be revisited. See comment in RunTestMethod.
                        result.TestFailureException ??= HandleMethodException(ex, realException, TestClassName, TestMethodName);
                    }

                    if (result.Outcome != UTF.UnitTestOutcome.Passed)
                    {
                        result.Outcome = ex is AssertInconclusiveException || ex.InnerException is AssertInconclusiveException
                            ? UTF.UnitTestOutcome.Inconclusive
                            : UTF.UnitTestOutcome.Failed;
                    }
                }
            }

            // if we get here, the test method did not throw the exception
            // if the user specified that the test was going to throw an exception, and
            // it did not, we should fail the test
            // We only perform this check if the test initialize passes and the test method is actually run.
            if (hasTestInitializePassed && !isExceptionThrown && TestMethodOptions.ExpectedException != null)
            {
                result.TestFailureException = new TestFailedException(
                    ObjectModelUnitTestOutcome.Failed,
                    TestMethodOptions.ExpectedException.NoExceptionMessage);
                result.Outcome = UTF.UnitTestOutcome.Failed;
            }
        }
        catch (Exception exception)
        {
            testRunnerException = exception;
        }

        // Set the current tests outcome before cleanup so it can be used in the cleanup logic.
        TestMethodOptions.TestContext!.SetOutcome(result.Outcome);

        // TestCleanup can potentially be a long running operation which shouldn't ideally be in a finally block.
        // Pulling it out so extension writers can abort custom cleanups if need be. Having this in a finally block
        // does not allow a thread abort exception to be raised within the block but throws one after finally is executed
        // crashing the process. This was blocking writing an extension for Dynamic Timeout in VSO.
        if (classInstance != null && testContextSetup)
        {
            RunTestCleanupMethod(classInstance, result);
        }

        return testRunnerException != null ? throw testRunnerException : result;
    }

    [SuppressMessage("Microsoft.Design", "CA1031:DoNotCatchGeneralExceptionTypes", Justification = "Requirement is to handle all kinds of user exceptions and message appropriately.")]
    private bool IsExpectedException(Exception ex, TestResult result)
    {
        // if the user specified an expected exception, we need to check if this
        // exception was thrown. If it was thrown, we should pass the test. In
        // case a different exception was thrown, the test is seen as failure
        if (TestMethodOptions.ExpectedException == null)
        {
            return false;
        }

        Exception exceptionFromVerify;
        try
        {
            // If the expected exception attribute's Verify method returns, then it
            // considers this exception as expected, so the test passed
            TestMethodOptions.ExpectedException.Verify(ex);
            return true;
        }
        catch (Exception verifyEx)
        {
            bool isTargetInvocationError = verifyEx is TargetInvocationException;
            if (isTargetInvocationError && verifyEx.InnerException != null)
            {
                exceptionFromVerify = verifyEx.InnerException;
            }
            else
            {
                // Verify threw an exception, so the expected exception attribute does not
                // consider this exception to be expected. Include the exception message in
                // the test result.
                exceptionFromVerify = verifyEx;
            }
        }

        // See if the verification exception (thrown by the expected exception
        // attribute's Verify method) is an AssertInconclusiveException. If so, set
        // the test outcome to Inconclusive.
        result.TestFailureException = new TestFailedException(
            exceptionFromVerify is AssertInconclusiveException
                ? ObjectModelUnitTestOutcome.Inconclusive
                : ObjectModelUnitTestOutcome.Failed,
            exceptionFromVerify.TryGetMessage(),
            ex.TryGetStackTraceInformation());
        return false;
    }

    private static Exception GetRealException(Exception ex)
    {
        if (ex is TargetInvocationException)
        {
            DebugEx.Assert(ex.InnerException != null, "Inner exception of TargetInvocationException is null. This should occur because we should have caught this case above.");

            // Our reflected call will typically always get back a TargetInvocationException
            // containing the real exception thrown by the test method as its inner exception
            return ex.InnerException;
        }
        else
        {
            return ex;
        }
    }

    /// <summary>
    /// Handles the exception that is thrown by a test method. The exception can either
    /// be expected or not expected.
    /// </summary>
    /// <param name="ex">Exception that was thrown.</param>
    /// <param name="className">The class name.</param>
    /// <param name="methodName">The method name.</param>
    /// <returns>Test framework exception with details.</returns>
    private static TestFailedException HandleMethodException(Exception ex, Exception realException, string className, string methodName)
    {
        DebugEx.Assert(ex != null, "exception should not be null.");

        string errorMessage;
        if (ex is TargetInvocationException && ex.InnerException == null)
        {
            errorMessage = string.Format(CultureInfo.CurrentCulture, Resource.UTA_FailedToGetTestMethodException, className, methodName);
            return new TestFailedException(ObjectModelUnitTestOutcome.Error, errorMessage);
        }

        if (ex is TestFailedException testFailedException)
        {
            return testFailedException;
        }

        // Get the real exception thrown by the test method
        if (realException.TryGetUnitTestAssertException(out UTF.UnitTestOutcome outcome, out string? exceptionMessage, out StackTraceInformation? exceptionStackTraceInfo))
        {
            return new TestFailedException(outcome.ToUnitTestOutcome(), exceptionMessage, exceptionStackTraceInfo, realException);
        }

        errorMessage = string.Format(
            CultureInfo.CurrentCulture,
            Resource.UTA_TestMethodThrows,
            className,
            methodName,
            realException.GetFormattedExceptionMessage());

        // Handle special case of UI objects in TestMethod to suggest UITestMethod
        if (realException.HResult == -2147417842)
        {
            errorMessage = string.Format(CultureInfo.CurrentCulture, Resource.UTA_WrongThread, errorMessage);
        }

        StackTraceInformation? stackTrace = null;

        // For ThreadAbortException (that can be thrown only by aborting a thread as there's no public constructor)
        // there's no inner exception and exception itself contains reflection-related stack trace
        // (_RuntimeMethodHandle.InvokeMethodFast <- _RuntimeMethodHandle.Invoke <- UnitTestExecuter.RunTestMethod)
        // which has no meaningful info for the user. Thus, we do not show call stack for ThreadAbortException.
        if (realException.GetType().Name != "ThreadAbortException")
        {
            stackTrace = realException.GetStackTraceInformation();
        }

        return new TestFailedException(ObjectModelUnitTestOutcome.Failed, errorMessage, stackTrace, realException);
    }

    /// <summary>
    /// Runs TestCleanup methods of parent TestClass and base classes.
    /// </summary>
    /// <param name="classInstance">Instance of TestClass.</param>
    /// <param name="result">Instance of TestResult.</param>
    [SuppressMessage("Microsoft.Design", "CA1031:DoNotCatchGeneralExceptionTypes", Justification = "Requirement is to handle all kinds of user exceptions and message appropriately.")]
    private void RunTestCleanupMethod(object classInstance, TestResult result)
    {
        DebugEx.Assert(classInstance != null, "classInstance != null");
        DebugEx.Assert(result != null, "result != null");

        MethodInfo? testCleanupMethod = Parent.TestCleanupMethod;
        Exception? testCleanupException;
        try
        {
            try
            {
                // Test cleanups are called in the order of discovery
                // Current TestClass -> Parent -> Grandparent
                testCleanupException = testCleanupMethod is not null ? InvokeCleanupMethod(testCleanupMethod, classInstance) : null;
                var baseTestCleanupQueue = new Queue<MethodInfo>(Parent.BaseTestCleanupMethodsQueue);
                while (baseTestCleanupQueue.Count > 0 && testCleanupException is null)
                {
                    testCleanupMethod = baseTestCleanupQueue.Dequeue();
                    testCleanupException = testCleanupMethod is not null ? InvokeCleanupMethod(testCleanupMethod, classInstance) : null;
                }
            }
            finally
            {
#if NET6_0_OR_GREATER
                // If you implement IAsyncDisposable without calling the DisposeAsync this would result a resource leak.
                (classInstance as IAsyncDisposable)?.DisposeAsync().AsTask().Wait();
#endif
                (classInstance as IDisposable)?.Dispose();
            }
        }
        catch (Exception ex)
        {
            testCleanupException = ex;
        }

        // If testCleanup was successful, then don't do anything
        if (testCleanupException == null)
        {
            return;
        }

        // If the exception is already a `TestFailedException` we throw it as-is
        if (testCleanupException is TestFailedException)
        {
            result.Outcome = UTF.UnitTestOutcome.Failed;
            result.TestFailureException = testCleanupException;
            return;
        }

        var cleanupError = new StringBuilder();
        var cleanupStackTrace = new StringBuilder();
        if (result.TestFailureException is TestFailedException testFailureException)
        {
            if (!StringEx.IsNullOrEmpty(testFailureException.Message))
            {
                cleanupError.Append(testFailureException.Message);
                cleanupError.AppendLine();
            }

            if (!StringEx.IsNullOrEmpty(testFailureException.StackTraceInformation?.ErrorStackTrace))
            {
                cleanupStackTrace.Append(testFailureException.StackTraceInformation.ErrorStackTrace);
                cleanupStackTrace.Append(Environment.NewLine);
                cleanupStackTrace.Append(Resource.UTA_CleanupStackTrace);
                cleanupStackTrace.Append(Environment.NewLine);
            }
        }

        Exception realException = testCleanupException.GetRealException();
        string formattedExceptionMessage = realException.GetFormattedExceptionMessage();

        if (testCleanupMethod != null)
        {
            cleanupError.AppendFormat(
                CultureInfo.CurrentCulture,
                Resource.UTA_CleanupMethodThrows,
                TestClassName,
                testCleanupMethod.Name,
                formattedExceptionMessage);
        }
        else
        {
            cleanupError.AppendFormat(
                CultureInfo.CurrentCulture,
                Resource.UTA_CleanupMethodThrowsGeneralError,
                TestClassName,
                formattedExceptionMessage);
        }

        StackTraceInformation? cleanupStackTraceInfo = null;
        StackTraceInformation? realExceptionStackTraceInfo = realException.TryGetStackTraceInformation();
        if (realExceptionStackTraceInfo != null)
        {
            cleanupStackTrace.Append(realExceptionStackTraceInfo.ErrorStackTrace);
            cleanupStackTraceInfo ??= realExceptionStackTraceInfo;
        }

        StackTraceInformation? finalStackTraceInfo = null;
        if (cleanupStackTrace.Length != 0)
        {
            finalStackTraceInfo = cleanupStackTraceInfo != null
                ? new StackTraceInformation(
                    cleanupStackTrace.ToString(),
                    cleanupStackTraceInfo.ErrorFilePath,
                    cleanupStackTraceInfo.ErrorLineNumber,
                    cleanupStackTraceInfo.ErrorColumnNumber)
                : new StackTraceInformation(cleanupStackTrace.ToString());
        }

        result.Outcome = result.Outcome.GetMoreImportantOutcome(realException is AssertInconclusiveException ? UTF.UnitTestOutcome.Inconclusive : UTF.UnitTestOutcome.Failed);
        result.TestFailureException = new TestFailedException(result.Outcome.ToUnitTestOutcome(), cleanupError.ToString(), finalStackTraceInfo, realException);
    }

    /// <summary>
    /// Runs TestInitialize methods of parent TestClass and the base classes.
    /// </summary>
    /// <param name="classInstance">Instance of TestClass.</param>
    /// <param name="result">Instance of TestResult.</param>
    /// <returns>True if the TestInitialize method(s) did not throw an exception.</returns>
    [SuppressMessage("Microsoft.Design", "CA1031:DoNotCatchGeneralExceptionTypes", Justification = "Requirement is to handle all kinds of user exceptions and message appropriately.")]
    private bool RunTestInitializeMethod(object classInstance, TestResult result)
    {
        DebugEx.Assert(classInstance != null, "classInstance != null");
        DebugEx.Assert(result != null, "result != null");

        MethodInfo? testInitializeMethod = null;
        Exception? testInitializeException = null;

        try
        {
            // TestInitialize methods for base classes are called in reverse order of discovery
            // Grandparent -> Parent -> Child TestClass
            var baseTestInitializeStack = new Stack<MethodInfo>(Parent.BaseTestInitializeMethodsQueue);
            while (baseTestInitializeStack.Count > 0)
            {
                testInitializeMethod = baseTestInitializeStack.Pop();
                testInitializeException = testInitializeMethod is not null ? InvokeInitializeMethod(testInitializeMethod, classInstance) : null;
                if (testInitializeException is not null)
                {
                    break;
                }
            }

            if (testInitializeException == null)
            {
                testInitializeMethod = Parent.TestInitializeMethod;
                testInitializeException = testInitializeMethod is not null ? InvokeInitializeMethod(testInitializeMethod, classInstance) : null;
            }
        }
        catch (Exception ex)
        {
            testInitializeException = ex;
        }

        // If testInitialization was successful, then don't do anything
        if (testInitializeException == null)
        {
            return true;
        }

        // If the exception is already a `TestFailedException` we throw it as-is
        if (testInitializeException is TestFailedException)
        {
            result.Outcome = UTF.UnitTestOutcome.Failed;
            result.TestFailureException = testInitializeException;
            return false;
        }

        Exception realException = testInitializeException.GetRealException();

        // Prefix the exception message with the exception type name as prefix when exception is not assert exception.
        string exceptionMessage = realException is UnitTestAssertException
            ? realException.TryGetMessage()
            : ExceptionHelper.GetFormattedExceptionMessage(realException);
        string errorMessage = string.Format(
            CultureInfo.CurrentCulture,
            Resource.UTA_InitMethodThrows,
            TestClassName,
            testInitializeMethod?.Name,
            exceptionMessage);
        StackTraceInformation? stackTrace = realException.GetStackTraceInformation();

        result.Outcome = realException is AssertInconclusiveException ? UTF.UnitTestOutcome.Inconclusive : UTF.UnitTestOutcome.Failed;
        result.TestFailureException = new TestFailedException(
            result.Outcome.ToUnitTestOutcome(),
            errorMessage,
            stackTrace,
            realException);

        return false;
    }

    private TestFailedException? InvokeInitializeMethod(MethodInfo methodInfo, object classInstance)
    {
        int? timeout = null;
        if (Parent.TestInitializeMethodTimeoutMilliseconds.TryGetValue(methodInfo, out int localTimeout))
        {
            timeout = localTimeout;
        }

        return MethodRunner.RunWithTimeoutAndCancellation(
            () => methodInfo.InvokeAsSynchronousTask(classInstance, null),
            new CancellationTokenSource(),
            timeout,
            methodInfo,
            Resource.TestInitializeWasCancelled,
            Resource.TestInitializeTimedOut);
    }

    private TestFailedException? InvokeCleanupMethod(MethodInfo methodInfo, object classInstance)
    {
        int? timeout = null;
        if (Parent.TestCleanupMethodTimeoutMilliseconds.TryGetValue(methodInfo, out int localTimeout))
        {
            timeout = localTimeout;
        }

        return MethodRunner.RunWithTimeoutAndCancellation(
            () => methodInfo.InvokeAsSynchronousTask(classInstance, null),
            new CancellationTokenSource(),
            timeout,
            methodInfo,
            Resource.TestCleanupWasCancelled,
            Resource.TestCleanupTimedOut);
    }

    /// <summary>
    /// Sets the <see cref="TestContext"/> on <paramref name="classInstance"/>.
    /// </summary>
    /// <param name="classInstance">
    /// Reference to instance of TestClass.
    /// </param>
    /// <param name="result">
    /// Reference to instance of <see cref="TestResult"/>.
    /// </param>
    /// <returns>
    /// True if there no exceptions during set context operation.
    /// </returns>
    [SuppressMessage("Microsoft.Design", "CA1031:DoNotCatchGeneralExceptionTypes", Justification = "Requirement is to handle all kinds of user exceptions and message appropriately.")]
    private bool SetTestContext(object classInstance, TestResult result)
    {
        DebugEx.Assert(classInstance != null, "classInstance != null");
        DebugEx.Assert(result != null, "result != null");

        try
        {
            if (Parent.TestContextProperty != null && Parent.TestContextProperty.CanWrite)
            {
                Parent.TestContextProperty.SetValue(classInstance, TestMethodOptions.TestContext);
            }

            return true;
        }
        catch (Exception ex)
        {
            Exception realException = ex.GetRealException();
            string errorMessage = string.Format(
                CultureInfo.CurrentCulture,
                Resource.UTA_TestContextSetError,
                TestClassName,
                realException.GetFormattedExceptionMessage());

            result.Outcome = UTF.UnitTestOutcome.Failed;
            StackTraceInformation? stackTraceInfo = realException.GetStackTraceInformation();
            result.TestFailureException = new TestFailedException(ObjectModelUnitTestOutcome.Failed, errorMessage, stackTraceInfo);
        }

        return false;
    }

    /// <summary>
    /// Creates an instance of TestClass. The TestMethod is invoked on this instance.
    /// </summary>
    /// <param name="result">
    /// Reference to the <see cref="TestResult"/> for this TestMethod.
    /// Outcome and TestFailureException are updated based on instance creation.
    /// </param>
    /// <returns>
    /// An instance of the TestClass. Returns null if there are errors during class instantiation.
    /// </returns>
    [SuppressMessage("Microsoft.Design", "CA1031:DoNotCatchGeneralExceptionTypes", Justification = "Requirement is to handle all kinds of user exceptions and message appropriately.")]
    private object? CreateTestClassInstance(TestResult result)
    {
        object? classInstance = null;
        try
        {
            classInstance = Parent.Constructor.Invoke(null);
        }
        catch (Exception ex)
        {
            if (ex == null)
            {
                // It seems that ex can be null in some rare cases when initialization fails in native code.
                // Get our own exception with a stack trace to satisfy GetStackTraceInformation.
                try
                {
                    throw new InvalidOperationException(Resource.UTA_UserCodeThrewNullValueException);
                }
                catch (Exception exception)
                {
                    ex = exception;
                }
            }

            // In most cases, exception will be TargetInvocationException with real exception wrapped
            // in the InnerException; or user code throws an exception.
            // It also seems that in rare cases the ex can be null.
            Exception actualException = ex.InnerException ?? ex;
            string exceptionMessage = actualException.GetFormattedExceptionMessage();
            StackTraceInformation? stackTraceInfo = actualException.GetStackTraceInformation();

            string errorMessage = string.Format(
                CultureInfo.CurrentCulture,
                Resource.UTA_InstanceCreationError,
                TestClassName,
                exceptionMessage);

            result.Outcome = UTF.UnitTestOutcome.Failed;
            result.TestFailureException = new TestFailedException(ObjectModelUnitTestOutcome.Failed, errorMessage, stackTraceInfo);
        }

        return classInstance;
    }

    /// <summary>
    /// Execute test with a timeout.
    /// </summary>
    /// <param name="arguments">The arguments to be passed.</param>
    /// <returns>The result of execution.</returns>
    [SuppressMessage("Microsoft.Design", "CA1031:DoNotCatchGeneralExceptionTypes", Justification = "Requirement is to handle all kinds of user exceptions and message appropriately.")]
    private TestResult ExecuteInternalWithTimeout(object?[]? arguments)
    {
        DebugEx.Assert(IsTimeoutSet, "Timeout should be set");

        TestResult? result = null;
        Exception? failure = null;

        void ExecuteAsyncAction()
        {
            try
            {
                result = ExecuteInternal(arguments);
            }
            catch (Exception ex)
            {
                failure = ex;
            }
        }

        CancellationToken cancelToken = TestMethodOptions.TestContext!.Context.CancellationTokenSource!.Token;
        if (PlatformServiceProvider.Instance.ThreadOperations.Execute(ExecuteAsyncAction, TestMethodOptions.Timeout, cancelToken))
        {
            if (failure != null)
            {
                throw failure;
            }

            DebugEx.Assert(result is not null, "result is not null");
            return result;
        }
        else
        {
            // Timed out or canceled
            string errorMessage = string.Format(CultureInfo.CurrentCulture, Resource.Execution_Test_Timeout, TestMethodName);
            if (TestMethodOptions.TestContext.Context.CancellationTokenSource.IsCancellationRequested)
            {
                errorMessage = string.Format(CultureInfo.CurrentCulture, Resource.Execution_Test_Cancelled, TestMethodName);
            }
            else
            {
                // Cancel the token source as test has timed out
                TestMethodOptions.TestContext.Context.CancellationTokenSource.Cancel();
            }

            TestResult timeoutResult = new() { Outcome = UTF.UnitTestOutcome.Timeout, TestFailureException = new TestFailedException(ObjectModelUnitTestOutcome.Timeout, errorMessage) };
            return timeoutResult;
        }
    }
}
